<?xml version="1.0"?>
<!--cd ~/catkin_ws/src roslaunch urdf_tutorial display.launch model:="custom_robotic_arm/urdf/robotic_arm.urdf"
-->
<robot name="robotic_arm">
    <link name="world"/>
    <!--ONE-->
        <link name="base_link">
            <visual>
                <geometry>
                    <box size="0.2 0.2 0.1"/>
                </geometry>
                <material name = "Blue">
                    <color rgba ="0.0 0.0 1.0 1.0"/>
                </material>
                <origin xyz=" 0.0 0.0 0.05" rpy ="0.0 0.0 0.0"/>
            </visual>
            <collision>
                <geometry>
                    <box size="0.2 0.2 0.1"/>
                </geometry>
                 <origin xyz=" 0.0 0.0 0.05" rpy ="0.0 0.0 0.0"/>
            </collision>
        </link>
        <joint name="fixed_base" type = "fixed">
        <parent link ="world"/>
        <child link ="base_link"/>
        </joint>

    <!--ONE LINK-->
        <link name="One">
            <visual>
                <geometry>
                    <cylinder radius="0.05" length ="0.15"/>
                </geometry>
                <material name = "Blue">
                    <color rgba ="0.0 0.0 1.0 1.0"/>
                </material>
                <origin xyz=" 0.0 -0.125 0.0" rpy ="1.5708 0.0 0.0"/>
                <!--Its the relation between joind and the body in distance-->>
            </visual>
            <collision>
                <geometry>
                    <cylinder radius="0.05" length ="0.15"/>
                </geometry>
               <origin xyz=" 0.0 -0.125 0.0" rpy ="1.5708 0.0 0.0"/>
            </collision>
        </link>
        <joint name="One_joint" type = "revolute">
        <limit lower="-2.8798" upper="2.8798" effort="100.0" velocity="1.0"/>
        <!--(pi - pi/12 = 2.8798)-->
            <parent link ="base_link"/>
            <child link ="One"/>
            <axis xyz = "0.0 1.0 0.0"/>
            <origin xyz = "0.0 0.0 0.3" rpy = "1.5708 0.0 1.5708"/>
        </joint>

    <!--Two LINK-->
        <link name="Two">
            <visual>
                <geometry>
                    <cylinder radius="0.05" length ="0.1"/>
                </geometry>
                <material name = "Blue">
                    <color rgba ="0.0 0.0 1.0 1.0"/>
                </material>
                <origin xyz="0.0 0.0 0.0" rpy ="1.5708  0.0 0.0"/>
                <!--Its the relation between joind and the body in distance-->>
            </visual>
            <collision>
                <geometry>
                    <cylinder radius="0.05" length ="0.1"/>
                </geometry>
               <origin xyz="0.0 0.0 0.0" rpy ="1.5708  0.0 0.0"/>
            </collision>
        </link>
        <joint name="Two_joint" type = "revolute">
        <limit lower="-1.5708" upper="1.5708" effort="100.0" velocity="1.0"/>
        <!--(pi/2 = 1.5708)-->
            <parent link ="One"/>
            <child link ="Two"/>
            <axis xyz = "0.0 -1.0 0.0"/>
            <origin xyz = "0.0 0.0 0.0" rpy = "-1.5708 0.0 0.0"/>
            <!--This is relation between parent and child joint-->>
        </joint>

    <!--Three LINK-->
        <link name="Three">
            <visual>
                <geometry>
                    <cylinder radius="0.05" length ="0.2"/>
                </geometry>
                <material name = "Blue">
                    <color rgba ="0.0 0.0 1.0 1.0"/>
                </material>
                <origin xyz=" 0.0 -0.15 0.0" rpy ="1.5708 0.0 0.0"/>
                <!--Its the relation between joind and the body in distance-->>
            </visual>
            <collision>
                <geometry>
                    <cylinder radius="0.05" length ="0.2"/>
                </geometry>
                <origin xyz=" 0.0 -0.15 0.0" rpy ="1.5708 0.0 0.0"/>
            </collision>
        </link>
        <joint name="Three_joint" type = "revolute">
        <limit lower="-2.8798" upper="2.8798" effort="100.0" velocity="1.0"/>
        <!--(pi - pi/12 = 2.8798)-->
            <parent link ="Two"/>
            <child link ="Three"/>
            <axis xyz = "0.0 1.0 0.0"/>
            <origin xyz = "0.0 0.0 0.3" rpy = "1.5708 0.0 0.0"/>
            <!--This is relation between parent and child joint-->>
        </joint>

    <!--Four LINK-->
        <link name="Four">
            <visual>
                <geometry>
                    <cylinder radius="0.05" length ="0.1"/>
                </geometry>
                <material name = "Blue">
                    <color rgba ="0.0 0.0 1.0 1.0"/>
                </material>
                <origin xyz="0.0 0.0 0.0" rpy ="1.5708  0.0 0.0"/>
                <!--Its the relation between joind and the body in distance-->>
            </visual>
            <collision>
                <geometry>
                    <cylinder radius="0.05" length ="0.1"/>
                </geometry>
                <origin xyz="0.0 0.0 0.0" rpy ="1.5708  0.0 0.0"/>
            </collision>
        </link>
        <joint name="Four_joint" type = "revolute">
        <limit lower="-2.8798" upper="2.8798" effort="100.0" velocity="1.0"/>
        <!--(pi - pi/12 = 2.8798)-->
            <parent link ="Three"/>
            <child link ="Four"/>
            <axis xyz = "0.0 -1.0 0.0"/>
            <origin xyz = "0.0 0.0 0.0" rpy = "-1.5708 0.0 0.0"/>
            <!--This is relation between parent and child joint-->>
        </joint>

    <!--Five LINK-->
        <link name="Five">
            <visual>
                <geometry>
                    <cylinder radius="0.05" length ="0.2"/>
                </geometry>
                <material name = "Blue">
                    <color rgba ="0.0 0.0 1.0 1.0"/>
                </material>
                <origin xyz=" 0.0 -0.15 0.0" rpy ="1.5708 0.0 0.0"/>
                <!--Its the relation between joind and the body in distance-->>
            </visual>
            <collision>
                <geometry>
                    <cylinder radius="0.05" length ="0.2"/>
                </geometry>
                <origin xyz=" 0.0 -0.15 0.0" rpy ="1.5708 0.0 0.0"/>
            </collision>
        </link>
        <joint name="Five_joint" type = "revolute">
        <limit lower="-2.8798" upper="2.8798" effort="100.0" velocity="1.0"/>
        <!--(pi - pi/12 = 2.8798)-->
            <parent link ="Four"/>
            <child link ="Five"/>
            <axis xyz = "0.0 1.0 0.0"/>
            <origin xyz = "0.0 0.0 0.3" rpy = "1.5708 0.0 0.0"/>
            <!--This is relation between parent and child joint-->>
        </joint>

    <!--Six-->
         <link name="Six">
            <visual>
                <geometry>
                    <cylinder radius="0.05" length ="0.1"/>
                </geometry>
                <material name = "Blue">
                    <color rgba ="0.0 0.0 1.0 1.0"/>
                </material>
                <origin xyz="0.0 0.0 0.0" rpy ="0.0 0.0 0.0"/>
                <!--Its the relation between joind and the body in distance-->>
            </visual>
            <collision>
                <geometry>
                    <cylinder radius="0.05" length ="0.1"/>
                </geometry>
                <origin xyz="0.0 0.0 0.0" rpy ="0.0 0.0 0.0"/>
            </collision>
        </link>

        <joint name="Six_joint" type = "revolute">
        <limit lower="-2.8798" upper="2.8798" effort="100.0" velocity="1.0"/>
        <!--(pi - pi/12 = 2.8798)-->
            <parent link ="Five"/>
            <child link ="Six"/>
            <axis xyz = "0.0 0.0 1.0"/>
            <origin xyz = "0.0 0.0 0.0" rpy = "0.0 0.0 0.0"/>
        </joint>

    <!--Aux-->
         <link name="Aux">
            <visual>
                <geometry>
                    <cylinder radius="0.05" length ="0.1"/>
                </geometry>
                <material name = "Blue">
                    <color rgba ="0.0 0.0 1.0 1.0"/>
                </material>
                <origin xyz="0.0 -0.05 0.0" rpy ="-1.5708 0.0 0.0"/>
                <!--Its the relation between joind and the body in distance-->>
            </visual>
            <collision>
                <geometry>
                    <cylinder radius="0.05" length ="0.1"/>
                </geometry>
                <origin xyz="0.0 -0.05 0.0" rpy ="-1.5708 0.0 0.0"/>
            </collision>
        </link>

        <joint name="Aux_joint" type = "fixed">
            <parent link ="Six"/>
            <child link ="Aux"/>
            <axis xyz = "0.0 0.0 1.0"/>
            <origin xyz = "0.0 0.15 0.0" rpy = "0.0 0.0 0.0"/>
        </joint>

    <!--Seven LINK-->
        <link name="Seven">
            <visual>
                <geometry>
                    <cylinder radius="0.05" length ="0.1"/>
                </geometry>
                <material name = "Blue">
                    <color rgba ="0.0 0.0 1.0 1.0"/>
                </material>
                <origin xyz=" 0.0 0.0 0.0" rpy ="1.5708 0.0 0.0"/>
                <!--Its the relation between joind and the body in distance-->>
            </visual>
            <collision>
                <geometry>
                    <cylinder radius="0.05" length ="0.1"/>
                </geometry>
                <origin xyz="0.0 0.0 0.0" rpy ="1.5708 0.0 0.0"/>
            </collision>
        </link>
        <joint name="Seven_joint" type = "revolute">
        <limit lower="-2.8798" upper="2.8798" effort="100.0" velocity="1.0"/>
        <!--(pi - pi/12 = 2.8798)-->
            <parent link ="Aux"/>
            <child link ="Seven"/>
            <axis xyz = "0.0 1.0 0.0"/>
            <origin xyz = "0.0 0.05 0.0" rpy = "1.5708  1.5708  0.0"/>
            <!--This is relation between parent and child joint-->>
        </joint>
    <!-- Gripper_BASE LINK-->
    <link name="Gripper_Base">
            <visual>
                <geometry>
                    <cylinder radius="0.05" length="0.15"/>
                </geometry>
                <material name = "Blue">
                    <color rgba ="0.0 0.0 1.0 1.0"/>
                </material>
                <origin xyz="0.0 0.0 -0.075" rpy="0.0 0.0 0.0"/>
                <!--Its the relation between joint and the body in distance-->
            </visual>
            <collision>
                <geometry>
                    <cylinder radius="0.05" length="0.15"/>
                </geometry>
                <origin xyz="0.0 0.0 -0.075" rpy="0.0 0.0 0.0"/>
            </collision>
    </link>

    <joint name="Gripper_Base_joint" type="fixed">
        <parent link="Seven"/>
        <child link="Gripper_Base"/>
        <axis xyz="0.0 0.0 1.0"/>
        <origin xyz="0.0 0 -0.2" rpy="0.0 3.1416 0.0 "/>
        <!--This origin is relation between parent and child joint-->     
    </joint>

    <!-- Left_finger LINK-->
    <link name="L_F">
            <visual>
                <geometry>
                    <box size="0.02 0.02 0.06"/>
                </geometry>
                <material name = "Blue">
                    <color rgba ="0.0 0.0 1.0 1.0"/>
                </material>
                <origin xyz="0.0 0.0 0.03" rpy="0.0 0.0 0.0"/>
                <!--Its the relation between joint and the body in distance-->
            </visual>
            <collision>
                <geometry>
                    <box size="0.02 0.02 0.06"/>
                </geometry>
                <origin xyz="0.0 0.0 0.03" rpy="0.0 0.0 0.0"/>
            </collision>
    </link>

    <joint name="L_F_joint" type="prismatic">
        <limit lower="-0.02" upper="0.02" effort="100.0" velocity="1.0"/>
        <parent link="Gripper_Base"/>
        <child link="L_F"/>
        <axis xyz="0.0 1 0"/>
        <origin xyz="0.0 0.03 0.0" />
        <!--This origin is relation between parent and child joint-->
        
    </joint>

    <!-- Right Finger LINK-->
    <link name="R_F">
            <visual>
                <geometry>
                    <box size="0.02 0.02 0.06"/>
                </geometry>
                <material name = "Blue">
                    <color rgba ="0.0 0.0 1.0 1.0"/>
                </material>
                <!--Its the relation between joint and the body in distance-->
            <origin xyz="0.0 0.0 0.03" rpy="0.0 0.0 0.0"/>
            </visual>
            <collision>
                <geometry>
                    <box size="0.02 0.02 0.06"/>
                </geometry>
                <origin xyz="0.0 0.0 0.03" rpy="0.0 0.0 0.0"/>
            </collision>
    </link>

    <joint name="R_F_joint" type="prismatic">
        <limit lower="0.02" upper="-0.02" effort="100.0" velocity="1.0"/>
        <parent link="Gripper_Base"/>
        <child link="R_F"/>
        <axis xyz="0.0 1 0"/>
        <origin xyz="0.0 -0.03 0.0" />
        <!--This origin is relation between parent and child joint--> 
    </joint>
</robot>